Workbook

Sheet Labeled sample
A1: app_name | B1: score | C1: content | D1: category | E1: notes | F1: mentions_mint
A2: Credit Karma | B2: 1 | C2: Horrible 😔 | D2: Other / off-topic | E2: vague negative, no specific issue | F2: no
A3: Credit Karma | B3: 1 | C3: Switching from Mint, I absolutely hate it. The whole app is a collection of ads. No longer useful. | D3: Privacy & trust | E3: about ads | F3: yes
A4: Credit Karma | B4: 1 | C4: Unable to log in no support absolutely. Complete Trash. update: This system completely total garbage will recommend CREDIT SESAME....... | D4: Customer support | E4: login problem; no category fits well | F4: no
A5: Credit Karma | B5: 1 | C5: this app is so predatory | D5: Privacy & trust | E5: vague; could also be Other | F5: no
A6: Credit Karma | B6: 1 | C6: This app keeps popping up automatically on my phone when I don't even have it installed on my phone. How can I stop this from happening? It's so annoying. | D6: Bugs & performance | E6: app appears without being installed | F6: no
A7: Credit Karma | B7: 1 | C7: Once Intuit acquires any product, it becomes the shitiest piece of software. I had an awesome experience with Mint until they decided to move to the Credit Karma Ads portal. Seriously, the most hated company 😒 | D7: Privacy & trust | E7: about ads; anger at Mint move | F7: yes
A8: Credit Karma | B8: 1 | C8: I like the app it's very helpful but it started to stop updating my credit score saying trouble connecting now I don't know what my actual score is | D8: Bugs & performance | E8: credit score not refreshing; not a bank sync issue | F8: no
A9: Credit Karma | B9: 1 | C9: The Credit Karma app wouldn't allow me to sign in with my fingerprint due to too many false positives, and it wouldn't let me log in using my password or PIN code. | D9: Bugs & performance | E9: login problem | F9: no
A10: Credit Karma | B10: 2 | C10: qĺpm | D10: Other / off-topic | E10: gibberish | F10: no
A11: Credit Karma | B11: 2 | C11: Great app | D11: Praise | E11: text and rating don't match | F11: no
A12: Credit Karma | B12: 2 | C12: closed my account for no reason | D12: Customer support | E12: account closed; account issue | F12: no
A13: Credit Karma | B13: 2 | C13: Compared to the Mint application that it supposedly replaced in the intuit suite, It is nearly useless except for the credit score feature and the countless ads. If you are a mint user and are being prompted to switch to credit karma, delay as long as possible. | D13: Privacy & trust | E13: about ads; also missing budgeting features | F13: yes
... A25: Credit Karma | B25: 3 | C25: 👍👍😄🌭 | D25: Praise | E25: emoji only | F25: no
A26: Credit Karma | B26: 4 | C26: Good app | D26: Praise | F26: no
A27: Credit Karma | B27: 4 | C27: Please bring back the old neon color. (Also stop asking me about my driving score. I don't own a car.) | D27: Usability & design | E27: also unwanted prompts (driving score) | F27: no
A28: Credit Karma | B28: 4 | C28: All is good except the GPS is not accurate many times. | D28: Bugs & performance | E28: GPS accuracy; unclear which feature | F28: no
A29: Credit Karma | B29: 4 | C29: good but getting more ad oriented | D29: Privacy & trust | E29: about ads | F29: no
A30: Credit Karma | B30: 4 | C30: great tool, for beginners as well as those more experienced with credit. it really helps that I'm notified when the creditors will be reporting to the credit agency | D30: Praise | F30: no
A31: Credit Karma | B31: 4 | C31: I have time in for better lighting on the phone I would have meet in web there nice. | D31: Other / off-topic | E31: unclear text | F31: no
A32: Credit Karma | B32: 4 | C32: I don't need everyone to know everything with all the scammers out there. | D32: Privacy & trust | E32: vague privacy concern | F32: no
A33: Credit Karma | B33: 4 | C33: Credit karma is one of the best. Apps to use and check your credit. | D33: Praise | F33: no
A34: Credit Karma | B34: 5 | C34: great | D34: Praise | F34: no
A35: Credit Karma | B35: 5 | C35: I Love This App | D35: Praise | F35: no
A36: Credit Karma | B36: 5 | C36: I enjoy keeping up with my credit score and it's fast and easy with Credit Karma. You also get much more info about your credit making it easier to spot issues. | D36: Praise | F36: no
A37: Credit Karma | B37: 5 | C37: This is a very easy app to use. | D37: Praise | F37: no
A38: Credit Karma | B38: 5 | C38: I've been using Ck for years now I love this app. It's helped so much. | D38: Praise | F38: no
A39: Credit Karma | B39: 5 | C39: Credit Karma is a must for those who want to take control of or manage their credit. This is one of the most necessary and useful apps for helping you reach your financial goals. Plus, it's free. | D39: Praise | F39: no
A40: Credit Karma | B40: 5 | C40: I didn't think my credit score would be as good as a 668. 10 to 15 years ago I had a few credit cards and got behind on my payments but finally got them paid off. Now I do not have any credit cards only a debit card and deposit account for my monthly retirement payment. I hope to improve my credit rating a bit. Thank you for your free credit rating service! | D40: Praise | F40: no
A41: Credit Karma | B41: 5 | C41: Great app to stay updated on your credit scores. Also, gives information & options to dispute accounts... well done CK | D41: Praise | F41: no
A42: Monarch Money | B42: 1 | C42: Can't even use my membership App requires new trial after signing into current | D42: Pricing & subscription | E42: paid membership not recognized; could be a bug | F42: no
A43: Monarch Money | B43: 1 | C43: only have yearly pay as an option | D43: Pricing & subscription | E43: no monthly option | F43: no
A44: Monarch Money | B44: 1 | C44: Pay to play kind of apps, fit for US and Canadians only. | D44: Pricing & subscription | E44: also region availability | F44: no
A45: Monarch Money | B45: 1 | C45: I downloaded it for a free trial today and it signed me up via the play store to be billed in 7 days, then I went back into the app and it says I have to pay now because I've used my trial. I never have used it and I guess now I never can. | D45: Pricing & subscription | E45: trial billing problem | F45: no
A46: Monarch Money | B46: 1 | C46: Requires monthly subscription. No thanks, I can track my own finances. Ironic that an app to help with your finances requires you pay a monthly bill. Edit to say them still trying to sell me on this bs is so sad XD | D46: Pricing & subscription | E46: also upselling | F46: no
A47: Monarch Money | B47: 1 | C47: Couldn't even get past the pay wall to see if I like the app. I'm not giving you my credit card information for a trial before I even know if I want to commit to the app. Waste of time, uninstalled. | D47: Pricing & subscription | E47: paywall before trial | F47: no
A48: Monarch Money | B48: 1 | C48: trying hard to cancel after free trial. cannot be done in app, which says I have to do that in play store. no joy. I WILL NEVER BUY AN APP WHICH CHEATS ITS WAY TO FUNDS BY MAKING IT THIS DIFFICULT TO CANCEL | D48: Pricing & subscription | E48: cancellation difficulty | F48: no
A49: Monarch Money | B49: 1 | C49: No actual free version. | D49: Pricing & subscription | E49: no free version | F49: no
A50: Monarch Money | B50: 2 | C50: no push notifications | D50: Missing features | E50: push notifications | F50: no
A51: Monarch Money | B51: 2 | C51: Similar functionality and design to Mint but more connection issues and data problems. I discovered monarch when I was looking for a replacement for Mint. Mint certainly wasn't perfect, but it was free and performed well. Monarch has much of the same functionality and similar design but I have more issues with Monach connecting to accounts. This is disappointing considering there is a cost to monarch and Mint was free. | D51: Bank connection / sync | E51: compares with Mint | F51: yes
...

Sheet Summary
A1: Category | B1: Credit Karma | C1: Rocket Money | D1: YNAB | E1: Monarch Money | F1: Total
A2: Bank connection / sync | B2: =COUNTIFS('Labeled sample'!$D$2:$D$161,$A2,'Labeled sample'!$A$2:$A$161,B$1) -> 1 | C2: =COUNTIFS('Labeled sample'!$D$2:$D$161,$A2,'Labeled sample'!$A$2:$A$161,C$1) -> 8 | D2: =COUNTIFS('Labeled sample'!$D$2:$D$161,$A2,'Labeled sample'!$A$2:$A$161,D$1) -> 2 | E2: =COUNTIFS('Labeled sample'!$D$2:$D$161,$A2,'Labeled sample'!$A$2:$A$161,E$1) -> 6 | F2: =SUM(B2:E2) -> 17
A3: Bugs & performance | B3: =COUNTIFS('Labeled sample'!$D$2:$D$161,$A3,'Labeled sample'!$A$2:$A$161,B$1) -> 5 | C3: =COUNTIFS('Labeled sample'!$D$2:$D$161,$A3,'Labeled sample'!$A$2:$A$161,C$1) -> 6 | D3: =COUNTIFS('Labeled sample'!$D$2:$D$161,$A3,'Labeled sample'!$A$2:$A$161,D$1) -> 1 | E3: =COUNTIFS('Labeled sample'!$D$2:$D$161,$A3,'Labeled sample'!$A$2:$A$161,E$1) -> 3 | F3: =SUM(B3:E3) -> 15
A4: Pricing & subscription | B4: =COUNTIFS('Labeled sample'!$D$2:$D$161,$A4,'Labeled sample'!$A$2:$A$161,B$1) -> 0 | C4: =COUNTIFS('Labeled sample'!$D$2:$D$161,$A4,'Labeled sample'!$A$2:$A$161,C$1) -> 8 | D4: =COUNTIFS('Labeled sample'!$D$2:$D$161,$A4,'Labeled sample'!$A$2:$A$161,D$1) -> 4 | E4: =COUNTIFS('Labeled sample'!$D$2:$D$161,$A4,'Labeled sample'!$A$2:$A$161,E$1) -> 11 | F4: =SUM(B4:E4) -> 23
A5: Usability & design | B5: =COUNTIFS('Labeled sample'!$D$2:$D$161,$A5,'Labeled sample'!$A$2:$A$161,B$1) -> 2 | C5: =COUNTIFS('Labeled sample'!$D$2:$D$161,$A5,'Labeled sample'!$A$2:$A$161,C$1) -> 1 | D5: =COUNTIFS('Labeled sample'!$D$2:$D$161,$A5,'Labeled sample'!$A$2:$A$161,D$1) -> 15 | E5: =COUNTIFS('Labeled sample'!$D$2:$D$161,$A5,'Labeled sample'!$A$2:$A$161,E$1) -> 3 | F5: =SUM(B5:E5) -> 21
A6: Missing features | B6: =COUNTIFS('Labeled sample'!$D$2:$D$161,$A6,'Labeled sample'!$A$2:$A$161,B$1) -> 0 | C6: =COUNTIFS('Labeled sample'!$D$2:$D$161,$A6,'Labeled sample'!$A$2:$A$161,C$1) -> 3 | D6: =COUNTIFS('Labeled sample'!$D$2:$D$161,$A6,'Labeled sample'!$A$2:$A$161,D$1) -> 6 | E6: =COUNTIFS('Labeled sample'!$D$2:$D$161,$A6,'Labeled sample'!$A$2:$A$161,E$1) -> 5 | F6: =SUM(B6:E6) -> 14
A7: Customer support | B7: =COUNTIFS('Labeled sample'!$D$2:$D$161,$A7,'Labeled sample'!$A$2:$A$161,B$1) -> 3 | C7: =COUNTIFS('Labeled sample'!$D$2:$D$161,$A7,'Labeled sample'!$A$2:$A$161,C$1) -> 0 | D7: =COUNTIFS('Labeled sample'!$D$2:$D$161,$A7,'Labeled sample'!$A$2:$A$161,D$1) -> 0 | E7: =COUNTIFS('Labeled sample'!$D$2:$D$161,$A7,'Labeled sample'!$A$2:$A$161,E$1) -> 0 | F7: =SUM(B7:E7) -> 3
A8: Privacy & trust | B8: =COUNTIFS('Labeled sample'!$D$2:$D$161,$A8,'Labeled sample'!$A$2:$A$161,B$1) -> 7 | C8: =COUNTIFS('Labeled sample'!$D$2:$D$161,$A8,'Labeled sample'!$A$2:$A$161,C$1) -> 2 | D8: =COUNTIFS('Labeled sample'!$D$2:$D$161,$A8,'Labeled sample'!$A$2:$A$161,D$1) -> 0 | E8: =COUNTIFS('Labeled sample'!$D$2:$D$161,$A8,'Labeled sample'!$A$2:$A$161,E$1) -> 0 | F8: =SUM(B8:E8) -> 9
A9: Praise | B9: =COUNTIFS('Labeled sample'!$D$2:$D$161,$A9,'Labeled sample'!$A$2:$A$161,B$1) -> 13 | C9: =COUNTIFS('Labeled sample'!$D$2:$D$161,$A9,'Labeled sample'!$A$2:$A$161,C$1) -> 12 | D9: =COUNTIFS('Labeled sample'!$D$2:$D$161,$A9,'Labeled sample'!$A$2:$A$161,D$1) -> 10 | E9: =COUNTIFS('Labeled sample'!$D$2:$D$161,$A9,'Labeled sample'!$A$2:$A$161,E$1) -> 12 | F9: =SUM(B9:E9) -> 47
A10: Other / off-topic | B10: =COUNTIFS('Labeled sample'!$D$2:$D$161,$A10,'Labeled sample'!$A$2:$A$161,B$1) -> 9 | C10: =COUNTIFS('Labeled sample'!$D$2:$D$161,$A10,'Labeled sample'!$A$2:$A$161,C$1) -> 0 | D10: =COUNTIFS('Labeled sample'!$D$2:$D$161,$A10,'Labeled sample'!$A$2:$A$161,D$1) -> 2 | E10: =COUNTIFS('Labeled sample'!$D$2:$D$161,$A10,'Labeled sample'!$A$2:$A$161,E$1) -> 0 | F10: =SUM(B10:E10) -> 11
A11: Total | B11: =SUM(B2:B10) -> 40 | C11: =SUM(C2:C10) -> 40 | D11: =SUM(D2:D10) -> 40 | E11: =SUM(E2:E10) -> 40 | F11: =SUM(F2:F10) -> 160
A13: Labels are an AI-drafted first pass for testing categories; review before use.
